// error handling

try {
    let A= _1;
} catch (error) {
    console.log(error.name
        
    )
}